Workbook

Sheet Final Results
C1: Data Provided by:
C2: SOEST Laboratory for
C3: Analtyical Biogeochemistry (S-LAB)
C4: University of Hawaii at Manoa
C5: 1000 Pope Rd
C6: Honolulu, HI 96822
C7: 808-956-5878
C9: Date Samples Received: | E9: 45575
C11: Project: | D11: Nelson/Rochette-Yu Tsuen
A13: Sample | B13: NPOC (mg/L) | C13: TN (mg/L) | E13: Sample | F13: NPOC (uM) | G13: TN (uM)
A14: ='Run File 11.14.24'!A17 -> F1_IN 06/02/24 12:00 | B14: ='Run File 11.14.24'!B17 -> 1.6666333 | C14: ='Run File 11.14.24'!C17 -> 0.16419833 | E14: =A14 -> F1_IN 06/02/24 12:00 | F14: =B14/12.0107*1000 -> 138.76238 | G14: =C14/14.0067*1000 -> 11.722842
A15: ='Run File 11.14.24'!A18 -> F2_IN 06/02/24 12:00 | B15: ='Run File 11.14.24'!B18 -> 1.7546333 | C15: ='Run File 11.14.24'!C18 -> 0.16780833 | E15: =A15 -> F2_IN 06/02/24 12:00 | F15: =B15/12.0107*1000 -> 146.08918 | G15: =C15/14.0067*1000 -> 11.980576
A16: ='Run File 11.14.24'!A19 -> T1 06/02/24 12:00 | B16: ='Run File 11.14.24'!B19 -> 2.5886333 | C16: ='Run File 11.14.24'!C19 -> 0.21105833 | E16: =A16 -> T1 06/02/24 12:00 | F16: =B16/12.0107*1000 -> 215.52727 | G16: =C16/14.0067*1000 -> 15.068384
A17: ='Run File 11.14.24'!A20 -> T2 06/02/24 12:00 | B17: ='Run File 11.14.24'!B20 -> 1.9146333 | C17: ='Run File 11.14.24'!C20 -> 0.20005833 | E17: =A17 -> T2 06/02/24 12:00 | F17: =B17/12.0107*1000 -> 159.41064 | G17: =C17/14.0067*1000 -> 14.283045
A18: ='Run File 11.14.24'!A21 -> T3 06/02/24 12:00 | B18: ='Run File 11.14.24'!B21 -> 2.4946333 | C18: ='Run File 11.14.24'!C21 -> 0.36035833 | E18: =A18 -> T3 06/02/24 12:00 | F18: =B18/12.0107*1000 -> 207.70091 | G18: =C18/14.0067*1000 -> 25.727568
A19: ='Run File 11.14.24'!A22 -> T4 06/02/24 12:00 | B19: ='Run File 11.14.24'!B22 -> 3.1026333 | C19: ='Run File 11.14.24'!C22 -> 0.20285833 | E19: =A19 -> T4 06/02/24 12:00 | F19: =B19/12.0107*1000 -> 258.32244 | G19: =C19/14.0067*1000 -> 14.48295
A20: ='Run File 11.14.24'!A23 -> T5 06/02/24 12:00 | B20: ='Run File 11.14.24'!B23 -> 1.7076333 | C20: ='Run File 11.14.24'!C23 -> 0.18605833 | E20: =A20 -> T5 06/02/24 12:00 | F20: =B20/12.0107*1000 -> 142.176 | G20: =C20/14.0067*1000 -> 13.283524
A21: ='Run File 11.14.24'!A24 -> T6 06/02/24 12:00 | B21: ='Run File 11.14.24'!B24 -> 2.2096333 | C21: ='Run File 11.14.24'!C24 -> 0.27075833 | E21: =A21 -> T6 06/02/24 12:00 | F21: =B21/12.0107*1000 -> 183.97207 | G21: =C21/14.0067*1000 -> 19.33063
A22: ='Run File 11.14.24'!A28 -> T7 06/02/24 12:00 | B22: ='Run File 11.14.24'!B28 -> 1.7666333 | C22: ='Run File 11.14.24'!C28 -> 0.19435833 | E22: =A22 -> T7 06/02/24 12:00 | F22: =B22/12.0107*1000 -> 147.08829 | G22: =C22/14.0067*1000 -> 13.876097
A23: ='Run File 11.14.24'!A29 -> T8 06/02/24 12:00 | B23: ='Run File 11.14.24'!B29 -> 1.6506333 | C23: ='Run File 11.14.24'!C29 -> 0.18945833 | E23: =A23 -> T8 06/02/24 12:00 | F23: =B23/12.0107*1000 -> 137.43024 | G23: =C23/14.0067*1000 -> 13.526265
A24: ='Run File 11.14.24'!A30 -> T9 06/02/24 12:00 | B24: ='Run File 11.14.24'!B30 -> 1.7396333 | C24: ='Run File 11.14.24'!C30 -> 0.17598833 | E24: =A24 -> T9 06/02/24 12:00 | F24: =B24/12.0107*1000 -> 144.8403 | G24: =C24/14.0067*1000 -> 12.564582
A25: ='Run File 11.14.24'!A31 -> T10 06/02/24 12:00 | B25: ='Run File 11.14.24'!B31 -> 2.1946333 | C25: ='Run File 11.14.24'!C31 -> 0.31915833 | E25: =A25 -> T10 06/02/24 12:00 | F25: =B25/12.0107*1000 -> 182.72318 | G25: =C25/14.0067*1000 -> 22.786119
A26: ='Run File 11.14.24'!A32 -> T11 06/02/24 12:00 | B26: ='Run File 11.14.24'!B32 -> 1.5456333 | C26: ='Run File 11.14.24'!C32 -> 0.19555833 | E26: =A26 -> T11 06/02/24 12:00 | F26: =B26/12.0107*1000 -> 128.68803 | G26: =C26/14.0067*1000 -> 13.961771
A27: ='Run File 11.14.24'!A33 -> T12 06/02/24 12:00 | B27: ='Run File 11.14.24'!B33 -> 1.8316333 | C27: ='Run File 11.14.24'!C33 -> 0.24225833 | E27: =A27 -> T12 06/02/24 12:00 | F27: =B27/12.0107*1000 -> 152.50013 | G27: =C27/14.0067*1000 -> 17.295889
A28: ='Run File 11.14.24'!A34 -> T13 06/02/24 12:00 | B28: ='Run File 11.14.24'!B34 -> 1.7776333 | C28: ='Run File 11.14.24'!C34 -> 0.19555833 | E28: =A28 -> T13 06/02/24 12:00 | F28: =B28/12.0107*1000 -> 148.00414 | G28: =C28/14.0067*1000 -> 13.961771
A29: ='Run File 11.19.24'!A17 -> T14 06/02/24 12:00 | B29: ='Run File 11.19.24'!B17 -> 1.6704 | C29: ='Run File 11.19.24'!C17 -> 0.15784 | E29: =A29 -> T14 06/02/24 12:00 | F29: =B29/12.0107*1000 -> 139.07599 | G29: =C29/14.0067*1000 -> 11.268893
A30: ='Run File 11.19.24'!A18 -> T15 06/02/24 12:00 | B30: ='Run File 11.19.24'!B18 -> 1.5954 | C30: ='Run File 11.19.24'!C18 -> 0.1594 | E30: =A30 -> T15 06/02/24 12:00 | F30: =B30/12.0107*1000 -> 132.83156 | G30: =C30/14.0067*1000 -> 11.380268
A31: ='Run File 11.19.24'!A19 -> T16 06/02/24 12:00 | B31: ='Run File 11.19.24'!B19 -> 1.6824 | C31: ='Run File 11.19.24'!C19 -> 0.17692 | E31: =A31 -> T16 06/02/24 12:00 | F31: =B31/12.0107*1000 -> 140.0751 | G31: =C31/14.0067*1000 -> 12.631098
A32: ='Run File 11.19.24'!A20 -> F1_IN 06/02/24 18:00 | B32: ='Run File 11.19.24'!B20 -> 1.3574 | C32: ='Run File 11.19.24'!C20 -> 0.22562 | E32: =A32 -> F1_IN 06/02/24 18:00 | F32: =B32/12.0107*1000 -> 113.01589 | G32: =C32/14.0067*1000 -> 16.108005
A33: ='Run File 11.19.24'!A21 -> F2_IN 06/02/24 18:00 | B33: ='Run File 11.19.24'!B21 -> 1.2484 | C33: ='Run File 11.19.24'!C21 -> 0.15196 | E33: =A33 -> F2_IN 06/02/24 18:00 | F33: =B33/12.0107*1000 -> 103.94065 | G33: =C33/14.0067*1000 -> 10.849094
A34: ='Run File 11.19.24'!A22 -> T1 06/02/24 18:00 | B34: ='Run File 11.19.24'!B22 -> 1.4204 | C34: ='Run File 11.19.24'!C22 -> 0.15567 | E34: =A34 -> T1 06/02/24 18:00 | F34: =B34/12.0107*1000 -> 118.26122 | G34: =C34/14.0067*1000 -> 11.113967
A35: ='Run File 11.19.24'!A23 -> T2 06/02/24 18:00 | B35: ='Run File 11.19.24'!B23 -> 1.2714 | C35: ='Run File 11.19.24'!C23 -> 0.15449 | E35: =A35 -> T2 06/02/24 18:00 | F35: =B35/12.0107*1000 -> 105.85561 | G35: =C35/14.0067*1000 -> 11.029721
A36: ='Run File 11.19.24'!A27 -> T3 06/02/24 18:00 | B36: ='Run File 11.19.24'!B27 -> 1.2044 | C36: ='Run File 11.19.24'!C27 -> 0.16682 | E36: =A36 -> T3 06/02/24 18:00 | F36: =B36/12.0107*1000 -> 100.27725 | G36: =C36/14.0067*1000 -> 11.910014
A37: ='Run File 11.19.24'!A28 -> T4 06/02/24 18:00 | B37: ='Run File 11.19.24'!B28 -> 1.5374 | C37: ='Run File 11.19.24'!C28 -> 0.15008 | E37: =A37 -> T4 06/02/24 18:00 | F37: =B37/12.0107*1000 -> 128.00253 | G37: =C37/14.0067*1000 -> 10.714872
A38: ='Run File 11.19.24'!A29 -> T5 06/02/24 18:00 | B38: ='Run File 11.19.24'!B29 -> 1.2934 | C38: ='Run File 11.19.24'!C29 -> 0.15911 | E38: =A38 -> T5 06/02/24 18:00 | F38: =B38/12.0107*1000 -> 107.68731 | G38: =C38/14.0067*1000 -> 11.359564
A39: ='Run File 11.19.24'!A30 -> T6 06/02/24 18:00 | B39: ='Run File 11.19.24'!B30 -> 1.5464 | C39: ='Run File 11.19.24'!C30 -> 0.22192 | E39: =A39 -> T6 06/02/24 18:00 | F39: =B39/12.0107*1000 -> 128.75186 | G39: =C39/14.0067*1000 -> 15.843846
A40: ='Run File 11.19.24'!A31 -> T7 06/02/24 18:00 | B40: ='Run File 11.19.24'!B31 -> 1.3214 | C40: ='Run File 11.19.24'!C31 -> 0.16377 | E40: =A40 -> T7 06/02/24 18:00 | F40: =B40/12.0107*1000 -> 110.01857 | G40: =C40/14.0067*1000 -> 11.692262
A41: ='Run File 11.19.24'!A32 -> T8 06/02/24 18:00 | B41: ='Run File 11.19.24'!B32 -> 5.1504 | C41: ='Run File 11.19.24'!C32 -> 0.16905 | E41: =A41 -> T8 06/02/24 18:00 | F41: =B41/12.0107*1000 -> 428.81764 | G41: =C41/14.0067*1000 -> 12.069224
A42: ='Run File 11.19.24'!A33 -> T9 06/02/24 18:00 | B42: ='Run File 11.19.24'!B33 -> 1.6884 | C42: ='Run File 11.19.24'!C33 -> 0.31972 | E42: =A42 -> T9 06/02/24 18:00 | F42: =B42/12.0107*1000 -> 140.57465 | G42: =C42/14.0067*1000 -> 22.826219
A43: ='Run File 11.19.24'!A34 -> T10 06/02/24 18:00 | B43: ='Run File 11.19.24'!B34 -> 1.4824 | C43: ='Run File 11.19.24'!C34 -> 0.24722 | E43: =A43 -> T10 06/02/24 18:00 | F43: =B43/12.0107*1000 -> 123.42328 | G43: =C43/14.0067*1000 -> 17.650125
...

Sheet Run File 11.14.24
A1: System | B1: TOCReg | D1: Deep Seawater Reference Material
A2: S/W Version | B2: 1
A3: User | B3: A.Whitworth | D3: NPOC certified reference value 0.504-0.516 mg/L: 42-43 uM
A4: Date | B4: 45610 | D4: TN certified reference value 0.434-0.448 mg/L: 31-32 uM
A5: Comments | B5: Nelson/Rochette-Yu Tsuen (10/10/24)
A9: Standards
A10: Range | B10: 0-5mg/L
A12: Raw data (mg/L) | E12: Unit conversion
A13: Sample | B13: NPOC (mg/L) | C13: TN (mg/L) | E13: Sample | F13: NPOC (uM) | G13: TN (uM)
A14: DIW | B14: -0.00495 | C14: 0 | E14: =A14 -> DIW | F14: =B14/12.0107*1000 -> -0.41213252 | G14: =C14/14.0067*1000 -> 0
A15: LNSW | B15: 0.904 | C15: 0.05286 | E15: =A15 -> LNSW | F15: =B15/12.0107*1000 -> 75.266221 | G15: =C15/14.0067*1000 -> 3.7739082
A16: DSWR [B24,L05-24] | B16: 0.51323333 | C16: 0.43385833 | E16: =A16 -> DSWR [B24,L05-24] | F16: =B16/12.0107*1000 -> 42.731342 | G16: =C16/14.0067*1000 -> 30.975057
A17: F1_IN 06/02/24 12:00 | B17: 1.6666333 | C17: 0.16419833 | E17: =A17 -> F1_IN 06/02/24 12:00 | F17: =B17/12.0107*1000 -> 138.76238 | G17: =C17/14.0067*1000 -> 11.722842
A18: F2_IN 06/02/24 12:00 | B18: 1.7546333 | C18: 0.16780833 | E18: =A18 -> F2_IN 06/02/24 12:00 | F18: =B18/12.0107*1000 -> 146.08918 | G18: =C18/14.0067*1000 -> 11.980576
A19: T1 06/02/24 12:00 | B19: 2.5886333 | C19: 0.21105833 | E19: =A19 -> T1 06/02/24 12:00 | F19: =B19/12.0107*1000 -> 215.52727 | G19: =C19/14.0067*1000 -> 15.068384
A20: T2 06/02/24 12:00 | B20: 1.9146333 | C20: 0.20005833 | E20: =A20 -> T2 06/02/24 12:00 | F20: =B20/12.0107*1000 -> 159.41064 | G20: =C20/14.0067*1000 -> 14.283045
A21: T3 06/02/24 12:00 | B21: 2.4946333 | C21: 0.36035833 | E21: =A21 -> T3 06/02/24 12:00 | F21: =B21/12.0107*1000 -> 207.70091 | G21: =C21/14.0067*1000 -> 25.727568
A22: T4 06/02/24 12:00 | B22: 3.1026333 | C22: 0.20285833 | E22: =A22 -> T4 06/02/24 12:00 | F22: =B22/12.0107*1000 -> 258.32244 | G22: =C22/14.0067*1000 -> 14.48295
A23: T5 06/02/24 12:00 | B23: 1.7076333 | C23: 0.18605833 | E23: =A23 -> T5 06/02/24 12:00 | F23: =B23/12.0107*1000 -> 142.176 | G23: =C23/14.0067*1000 -> 13.283524
A24: T6 06/02/24 12:00 | B24: 2.2096333 | C24: 0.27075833 | E24: =A24 -> T6 06/02/24 12:00 | F24: =B24/12.0107*1000 -> 183.97207 | G24: =C24/14.0067*1000 -> 19.33063
A25: DIW | B25: 0.00836 | C25: 0 | E25: =A25 -> DIW | F25: =B25/12.0107*1000 -> 0.69604603 | G25: =C25/14.0067*1000 -> 0
... A37: DSWR [B24,L05-24] | B37: 0.51833333 | C37: 0.44015833 | E37: =A37 -> DSWR [B24,L05-24] | F37: =B37/12.0107*1000 -> 43.155964 | G37: =C37/14.0067*1000 -> 31.424842

Sheet Run File 11.19.24
A1: System | B1: TOCReg | D1: Deep Seawater Reference Material
A2: S/W Version | B2: 1
A3: User | B3: A.Whitworth | D3: NPOC certified reference value 0.504-0.516 mg/L: 42-43 uM
A4: Date | B4: 45615 | D4: TN certified reference value 0.434-0.448 mg/L: 31-32 uM
A5: Comments | B5: Nelson/Rochette-Yu Tsuen (10/10/24)
A9: Standards
A10: Range | B10: 0-5mg/L
A12: Raw data (mg/L) | E12: Unit conversion
A13: Sample | B13: NPOC (mg/L) | C13: TN (mg/L) | E13: Sample | F13: NPOC (uM) | G13: TN (uM)
A14: DIW | B14: 0.00493 | C14: 0 | E14: =A14 -> DIW | F14: =B14/12.0107*1000 -> 0.41046733 | G14: =C14/14.0067*1000 -> 0
A15: LNSW | B15: 0.8907 | C15: 0.05811 | E15: =A15 -> LNSW | F15: =B15/12.0107*1000 -> 74.158875 | G15: =C15/14.0067*1000 -> 4.1487288
A16: DSWR [B24,L05-24] | B16: 0.505 | C16: 0.44482 | E16: =A16 -> DSWR [B24,L05-24] | F16: =B16/12.0107*1000 -> 42.045842 | G16: =C16/14.0067*1000 -> 31.757659
A17: T14 06/02/24 12:00 | B17: 1.6704 | C17: 0.15784 | E17: =A17 -> T14 06/02/24 12:00 | F17: =B17/12.0107*1000 -> 139.07599 | G17: =C17/14.0067*1000 -> 11.268893
A18: T15 06/02/24 12:00 | B18: 1.5954 | C18: 0.1594 | E18: =A18 -> T15 06/02/24 12:00 | F18: =B18/12.0107*1000 -> 132.83156 | G18: =C18/14.0067*1000 -> 11.380268
A19: T16 06/02/24 12:00 | B19: 1.6824 | C19: 0.17692 | E19: =A19 -> T16 06/02/24 12:00 | F19: =B19/12.0107*1000 -> 140.0751 | G19: =C19/14.0067*1000 -> 12.631098
A20: F1_IN 06/02/24 18:00 | B20: 1.3574 | C20: 0.22562 | E20: =A20 -> F1_IN 06/02/24 18:00 | F20: =B20/12.0107*1000 -> 113.01589 | G20: =C20/14.0067*1000 -> 16.108005
A21: F2_IN 06/02/24 18:00 | B21: 1.2484 | C21: 0.15196 | E21: =A21 -> F2_IN 06/02/24 18:00 | F21: =B21/12.0107*1000 -> 103.94065 | G21: =C21/14.0067*1000 -> 10.849094
A22: T1 06/02/24 18:00 | B22: 1.4204 | C22: 0.15567 | E22: =A22 -> T1 06/02/24 18:00 | F22: =B22/12.0107*1000 -> 118.26122 | G22: =C22/14.0067*1000 -> 11.113967
A23: T2 06/02/24 18:00 | B23: 1.2714 | C23: 0.15449 | E23: =A23 -> T2 06/02/24 18:00 | F23: =B23/12.0107*1000 -> 105.85561 | G23: =C23/14.0067*1000 -> 11.029721
A24: DIW | B24: 0.00819 | C24: 0 | E24: =A24 -> DIW | F24: =B24/12.0107*1000 -> 0.68189198 | G24: =C24/14.0067*1000 -> 0
A25: LNSW | B25: 0.8478 | C25: 0.05352 | E25: =A25 -> LNSW | F25: =B25/12.0107*1000 -> 70.58706 | G25: =C25/14.0067*1000 -> 3.8210285
... A78: DSWR [B24,L05-24] | B78: 0.5131 | C78: 0.43752 | E78: =A78 -> DSWR [B24,L05-24] | F78: =B78/12.0107*1000 -> 42.720241 | G78: =C78/14.0067*1000 -> 31.23648

Sheet Run File 11.21.24
A1: System | B1: TOCReg | D1: Deep Seawater Reference Material
A2: S/W Version | B2: 1
A3: User | B3: A.Whitworth | D3: NPOC certified reference value 0.504-0.516 mg/L: 42-43 uM
A4: Date | B4: 45617 | D4: TN certified reference value 0.434-0.448 mg/L: 31-32 uM
A5: Comments | B5: Nelson/Rochette-Yu Tsuen (10/10/24)
A9: Standards
A10: Range | B10: 0-5mg/L
A12: Raw data (mg/L) | E12: Unit conversion
A13: Sample | B13: NPOC (mg/L) | C13: TN (mg/L) | E13: Sample | F13: NPOC (uM) | G13: TN (uM)
A14: DIW | B14: -0.00055 | C14: 0 | E14: =A14 -> DIW | F14: =B14/12.0107*1000 -> -0.045792502 | G14: =C14/14.0067*1000 -> 0
A15: LNSW | B15: 0.8844 | C15: 0.05272 | E15: =A15 -> LNSW | F15: =B15/12.0107*1000 -> 73.634343 | G15: =C15/14.0067*1000 -> 3.763913
A16: DSWR [B24,L05-24] | B16: 0.50605 | C16: 0.4403 | E16: =A16 -> DSWR [B24,L05-24] | F16: =B16/12.0107*1000 -> 42.133265 | G16: =C16/14.0067*1000 -> 31.434956
A17: T8 06/03/24 6:00 | B17: 0.98725 | C17: 0.16429 | E17: =A17 -> T8 06/03/24 6:00 | F17: =B17/12.0107*1000 -> 82.197541 | G17: =C17/14.0067*1000 -> 11.729387
A18: T9 06/03/24 6:00 | B18: 1.81005 | C18: 0.2532 | E18: =A18 -> T9 06/03/24 6:00 | F18: =B18/12.0107*1000 -> 150.70312 | G18: =C18/14.0067*1000 -> 18.077063
A19: T10 06/03/24 6:00 | B19: 1.81005 | C19: 0.3016 | E19: =A19 -> T10 06/03/24 6:00 | F19: =B19/12.0107*1000 -> 150.70312 | G19: =C19/14.0067*1000 -> 21.532552
A20: T11 06/03/24 6:00 | B20: 1.04505 | C20: 1.1192 | E20: =A20 -> T11 06/03/24 6:00 | F20: =B20/12.0107*1000 -> 87.009916 | G20: =C20/14.0067*1000 -> 79.904617
A21: T13 06/03/24 6:00 | B21: 1.40505 | C21: 0.1728 | E21: =A21 -> T13 06/03/24 6:00 | F21: =B21/12.0107*1000 -> 116.98319 | G21: =C21/14.0067*1000 -> 12.336953
A22: T14 06/03/24 6:00 | B22: 1.52805 | C22: 0.2174 | E22: =A22 -> T14 06/03/24 6:00 | F22: =B22/12.0107*1000 -> 127.22406 | G22: =C22/14.0067*1000 -> 15.521143
A23: T15 06/03/24 6:00 | B23: 1.83905 | C23: 0.2247 | E23: =A23 -> T15 06/03/24 6:00 | F23: =B23/12.0107*1000 -> 153.11764 | G23: =C23/14.0067*1000 -> 16.042323
A24: T16 06/03/24 6:00 | B24: 1.09605 | C24: 0.16031 | E24: =A24 -> T16 06/03/24 6:00 | F24: =B24/12.0107*1000 -> 91.25613 | G24: =C24/14.0067*1000 -> 11.445237
A25: F1 06/04/24 12:00 | B25: 1.07305 | C25: 0.14723 | E25: =A25 -> F1 06/04/24 12:00 | F25: =B25/12.0107*1000 -> 89.341171 | G25: =C25/14.0067*1000 -> 10.511398
... A79: DSWR [B24,L05-24] | B79: 0.50805 | C79: 0.443 | E79: =A79 -> DSWR [B24,L05-24] | F79: =B79/12.0107*1000 -> 42.299783 | G79: =C79/14.0067*1000 -> 31.627721
