Workbook

Sheet Final Results
C1: Data Provided by:
C2: SOEST Laboratory for
C3: Analtyical Biogeochemistry (S-LAB)
C4: University of Hawaii at Manoa
C5: 1000 Pope Rd
C6: Honolulu, HI 96822
C7: 808-956-5878
C9: Date Samples Received: | E9: 45604
C11: Project: | D11: Nelson/Rochette-Yu Tsuen
A13: Sample | B13: NPOC (mg/L) | C13: TN (mg/L) | E13: Sample | F13: NPOC (uM) | G13: TN (uM)
A14: TAU824001 | B14: ='Run File 12.10.24'!B17 -> 0.55238 | C14: ='Run File 12.10.24'!C17 -> 0.11372143 | E14: =A14 -> TAU824001 | F14: =B14/12.0107*1000 -> 45.990658 | G14: =C14/14.0067*1000 -> 8.1190736
A15: TAU824002 | B15: ='Run File 12.10.24'!B18 -> 0.84268 | C15: ='Run File 12.10.24'!C18 -> 0.12811143 | E15: =A15 -> TAU824002 | F15: =B15/12.0107*1000 -> 70.160773 | G15: =C15/14.0067*1000 -> 9.1464391
A16: TAU824003 | B16: ='Run File 12.10.24'!B19 -> 0.81288 | C16: ='Run File 12.10.24'!C19 -> 0.11895143 | E16: =A16 -> TAU824003 | F16: =B16/12.0107*1000 -> 67.679652 | G16: =C16/14.0067*1000 -> 8.4924664
A17: TAU824004 | B17: ='Run File 12.10.24'!B20 -> 0.80188 | C17: ='Run File 12.10.24'!C20 -> 0.12222143 | E17: =A17 -> TAU824004 | F17: =B17/12.0107*1000 -> 66.763802 | G17: =C17/14.0067*1000 -> 8.7259261
A18: TAU824005 | B18: ='Run File 12.10.24'!B21 -> 0.81518 | C18: ='Run File 12.10.24'!C21 -> 0.11467143 | E18: =A18 -> TAU824005 | F18: =B18/12.0107*1000 -> 67.871148 | G18: =C18/14.0067*1000 -> 8.1868983
A19: TAU824006 | B19: ='Run File 12.10.24'!B22 -> 0.88138 | C19: ='Run File 12.10.24'!C22 -> 0.15295143 | E19: =A19 -> TAU824006 | F19: =B19/12.0107*1000 -> 73.3829 | G19: =C19/14.0067*1000 -> 10.919876
A20: TAU824007 | B20: ='Run File 12.10.24'!B23 -> 1.45788 | C20: ='Run File 12.10.24'!C23 -> 0.13608143 | E20: =A20 -> TAU824007 | F20: =B20/12.0107*1000 -> 121.38177 | G20: =C20/14.0067*1000 -> 9.7154525
A21: TAU824008 | B21: ='Run File 12.10.24'!B24 -> 0.85648 | C21: ='Run File 12.10.24'!C24 -> 0.13915143 | E21: =A21 -> TAU824008 | F21: =B21/12.0107*1000 -> 71.309749 | G21: =C21/14.0067*1000 -> 9.9346333
A22: TAU824009 | B22: ='Run File 12.10.24'!B25 -> 0.84448 | C22: ='Run File 12.10.24'!C25 -> 0.14204143 | E22: =A22 -> TAU824009 | F22: =B22/12.0107*1000 -> 70.31064 | G22: =C22/14.0067*1000 -> 10.140963
A23: TAU824010 | B23: ='Run File 12.10.24'!B26 -> 0.85078 | C23: ='Run File 12.10.24'!C26 -> 0.12274143 | E23: =A23 -> TAU824010 | F23: =B23/12.0107*1000 -> 70.835172 | G23: =C23/14.0067*1000 -> 8.7630512
A24: TAU824011 | B24: ='Run File 12.10.24'!B30 -> 0.86518 | C24: ='Run File 12.10.24'!C30 -> 0.11679143 | E24: =A24 -> TAU824011 | F24: =B24/12.0107*1000 -> 72.034103 | G24: =C24/14.0067*1000 -> 8.3382544
A25: TAU824012 | B25: ='Run File 12.10.24'!B31 -> 0.78298 | C25: ='Run File 12.10.24'!C31 -> 0.14068143 | E25: =A25 -> TAU824012 | F25: =B25/12.0107*1000 -> 65.190205 | G25: =C25/14.0067*1000 -> 10.043867
A26: TAU824013 | B26: ='Run File 12.10.24'!B32 -> 0.83248 | C26: ='Run File 12.10.24'!C32 -> 0.14051143 | E26: =A26 -> TAU824013 | F26: =B26/12.0107*1000 -> 69.311531 | G26: =C26/14.0067*1000 -> 10.03173
A27: TAU824014 | B27: ='Run File 12.10.24'!B33 -> 0.84388 | C27: ='Run File 12.10.24'!C33 -> 0.14528143 | E27: =A27 -> TAU824014 | F27: =B27/12.0107*1000 -> 70.260684 | G27: =C27/14.0067*1000 -> 10.372281
A28: TAU824015 | B28: ='Run File 12.10.24'!B34 -> 0.79598 | C28: ='Run File 12.10.24'!C34 -> 0.12159143 | E28: =A28 -> TAU824015 | F28: =B28/12.0107*1000 -> 66.272574 | G28: =C28/14.0067*1000 -> 8.6809476
A29: TAU824016 | B29: ='Run File 12.10.24'!B35 -> 0.86818 | C29: ='Run File 12.10.24'!C35 -> 0.12881143 | E29: =A29 -> TAU824016 | F29: =B29/12.0107*1000 -> 72.28388 | G29: =C29/14.0067*1000 -> 9.1964152
A30: TAU824017 | B30: ='Run File 12.10.24'!B36 -> 1.09488 | C30: ='Run File 12.10.24'!C36 -> 0.13422143 | E30: =A30 -> TAU824017 | F30: =B30/12.0107*1000 -> 91.158717 | G30: =C30/14.0067*1000 -> 9.5826589
A31: TAU824018 | B31: ='Run File 12.10.24'!B37 -> 0.78638 | C31: ='Run File 12.10.24'!C37 -> 0.14486143 | E31: =A31 -> TAU824018 | F31: =B31/12.0107*1000 -> 65.473286 | G31: =C31/14.0067*1000 -> 10.342295
A32: TAU824019 | B32: ='Run File 12.10.24'!B38 -> 0.54688 | C32: ='Run File 12.10.24'!C38 -> 0.10818143 | E32: =A32 -> TAU824019 | F32: =B32/12.0107*1000 -> 45.532733 | G32: =C32/14.0067*1000 -> 7.7235486
A33: TAU824020 | B33: ='Run File 12.10.24'!B39 -> 0.81208 | C33: ='Run File 12.10.24'!C39 -> 0.13028143 | E33: =A33 -> TAU824020 | F33: =B33/12.0107*1000 -> 67.613045 | G33: =C33/14.0067*1000 -> 9.301365
A34: TAU824021 | B34: ='Run File 12.10.24'!B43 -> 0.91468 | C34: ='Run File 12.10.24'!C43 -> 0.13541143 | E34: =A34 -> TAU824021 | F34: =B34/12.0107*1000 -> 76.155428 | G34: =C34/14.0067*1000 -> 9.6676183
A35: TAU824022 | B35: ='Run File 12.10.24'!B44 -> 0.84928 | C35: ='Run File 12.10.24'!C44 -> 0.13078143 | E35: =A35 -> TAU824022 | F35: =B35/12.0107*1000 -> 70.710283 | G35: =C35/14.0067*1000 -> 9.3370622
A36: TAU824023 | B36: ='Run File 12.10.24'!B45 -> 0.79728 | C36: ='Run File 12.10.24'!C45 -> 0.13631143 | E36: =A36 -> TAU824023 | F36: =B36/12.0107*1000 -> 66.38081 | G36: =C36/14.0067*1000 -> 9.7318732
A37: TAU824024 | B37: ='Run File 12.10.24'!B46 -> 0.76988 | C37: ='Run File 12.10.24'!C46 -> 0.12677143 | E37: =A37 -> TAU824024 | F37: =B37/12.0107*1000 -> 64.099511 | G37: =C37/14.0067*1000 -> 9.0507706
A38: TAU824025 | B38: ='Run File 12.10.24'!B47 -> 0.83638 | C38: ='Run File 12.10.24'!C47 -> 0.11343143 | E38: =A38 -> TAU824025 | F38: =B38/12.0107*1000 -> 69.636241 | G38: =C38/14.0067*1000 -> 8.0983692
A39: TAU824026 | B39: ='Run File 12.10.24'!B48 -> 0.85018 | C39: ='Run File 12.10.24'!C48 -> 0.13555143 | E39: =A39 -> TAU824026 | F39: =B39/12.0107*1000 -> 70.785217 | G39: =C39/14.0067*1000 -> 9.6776135
A40: TAU824027 | B40: ='Run File 12.10.24'!B49 -> 0.80258 | C40: ='Run File 12.10.24'!C49 -> 0.11802143 | E40: =A40 -> TAU824027 | F40: =B40/12.0107*1000 -> 66.822084 | G40: =C40/14.0067*1000 -> 8.4260696
A41: TAU824028 | B41: ='Run File 12.10.24'!B50 -> 0.95718 | C41: ='Run File 12.10.24'!C50 -> 0.13945143 | E41: =A41 -> TAU824028 | F41: =B41/12.0107*1000 -> 79.69394 | G41: =C41/14.0067*1000 -> 9.9560516
A42: TAU824029 | B42: ='Run File 12.10.24'!B51 -> 0.78598 | C42: ='Run File 12.10.24'!C51 -> 0.13547143 | E42: =A42 -> TAU824029 | F42: =B42/12.0107*1000 -> 65.439983 | G42: =C42/14.0067*1000 -> 9.6719019
A43: TAU824030 | B43: ='Run File 12.10.24'!B52 -> 0.84958 | C43: ='Run File 12.10.24'!C52 -> 0.13989143 | E43: =A43 -> TAU824030 | F43: =B43/12.0107*1000 -> 70.735261 | G43: =C43/14.0067*1000 -> 9.9874652
...

Sheet Run File 12.10.24
A1: System | B1: TOCReg | D1: Deep Seawater Reference Material
A2: S/W Version | B2: 1
A3: User | B3: A.Whitworth | D3: NPOC certified reference value 0.504-0.516 mg/L: 42-43 uM
A4: Date | B4: 45636 | D4: TN certified reference value 0.434-0.448 mg/L: 31-32 uM
A5: Comments | B5: Nelson/Rochette-Yu Tsuen (11/08/24)
A9: Standards
A10: Range | B10: 0-5mg/L
A12: Raw data (mg/L) | E12: Unit conversion
A13: Sample | B13: NPOC (mg/L) | C13: TN (mg/L) | E13: Sample | F13: NPOC (uM) | G13: TN (uM)
A14: DIW | B14: 0.00687 | C14: 0 | E14: =A14 -> DIW | F14: =B14/12.0107*1000 -> 0.57198998 | G14: =C14/14.0067*1000 -> 0
A15: LNSW | B15: 0.8907 | C15: 0.06102 | E15: =A15 -> LNSW | F15: =B15/12.0107*1000 -> 74.158875 | G15: =C15/14.0067*1000 -> 4.3564865
A16: DSWR [B24,L05-24] | B16: 0.50458 | C16: 0.44047143 | E16: =A16 -> DSWR [B24,L05-24] | F16: =B16/12.0107*1000 -> 42.010874 | G16: =C16/14.0067*1000 -> 31.447195
A17: 1 | B17: 0.55238 | C17: 0.11372143 | E17: =A17 -> 1 | F17: =B17/12.0107*1000 -> 45.990658 | G17: =C17/14.0067*1000 -> 8.1190736
A18: 2 | B18: 0.84268 | C18: 0.12811143 | E18: =A18 -> 2 | F18: =B18/12.0107*1000 -> 70.160773 | G18: =C18/14.0067*1000 -> 9.1464391
A19: 3 | B19: 0.81288 | C19: 0.11895143 | E19: =A19 -> 3 | F19: =B19/12.0107*1000 -> 67.679652 | G19: =C19/14.0067*1000 -> 8.4924664
A20: 4 | B20: 0.80188 | C20: 0.12222143 | E20: =A20 -> 4 | F20: =B20/12.0107*1000 -> 66.763802 | G20: =C20/14.0067*1000 -> 8.7259261
A21: 5 | B21: 0.81518 | C21: 0.11467143 | E21: =A21 -> 5 | F21: =B21/12.0107*1000 -> 67.871148 | G21: =C21/14.0067*1000 -> 8.1868983
A22: 6 | B22: 0.88138 | C22: 0.15295143 | E22: =A22 -> 6 | F22: =B22/12.0107*1000 -> 73.3829 | G22: =C22/14.0067*1000 -> 10.919876
A23: 7 | B23: 1.45788 | C23: 0.13608143 | E23: =A23 -> 7 | F23: =B23/12.0107*1000 -> 121.38177 | G23: =C23/14.0067*1000 -> 9.7154525
A24: 8 | B24: 0.85648 | C24: 0.13915143 | E24: =A24 -> 8 | F24: =B24/12.0107*1000 -> 71.309749 | G24: =C24/14.0067*1000 -> 9.9346333
A25: 9 | B25: 0.84448 | C25: 0.14204143 | E25: =A25 -> 9 | F25: =B25/12.0107*1000 -> 70.31064 | G25: =C25/14.0067*1000 -> 10.140963
A26: 10 | B26: 0.85078 | C26: 0.12274143 | E26: =A26 -> 10 | F26: =B26/12.0107*1000 -> 70.835172 | G26: =C26/14.0067*1000 -> 8.7630512
A27: DIW | B27: -0.00886 | C27: 0 | E27: =A27 -> DIW | F27: =B27/12.0107*1000 -> -0.73767557 | G27: =C27/14.0067*1000 -> 0
A28: LNSW | B28: 0.915 | C28: 0.06366 | E28: =A28 -> LNSW | F28: =B28/12.0107*1000 -> 76.182071 | G28: =C28/14.0067*1000 -> 4.5449678
A29: DSWR [B24,L05-24] | B29: 0.50738 | C29: 0.44907143 | E29: =A29 -> DSWR [B24,L05-24] | F29: =B29/12.0107*1000 -> 42.243999 | G29: =C29/14.0067*1000 -> 32.061187
A30: 11 | B30: 0.86518 | C30: 0.11679143 | E30: =A30 -> 11 | F30: =B30/12.0107*1000 -> 72.034103 | G30: =C30/14.0067*1000 -> 8.3382544
A31: 12 | B31: 0.78298 | C31: 0.14068143 | E31: =A31 -> 12 | F31: =B31/12.0107*1000 -> 65.190205 | G31: =C31/14.0067*1000 -> 10.043867
A32: 13 | B32: 0.83248 | C32: 0.14051143 | E32: =A32 -> 13 | F32: =B32/12.0107*1000 -> 69.311531 | G32: =C32/14.0067*1000 -> 10.03173
A33: 14 | B33: 0.84388 | C33: 0.14528143 | E33: =A33 -> 14 | F33: =B33/12.0107*1000 -> 70.260684 | G33: =C33/14.0067*1000 -> 10.372281
A34: 15 | B34: 0.79598 | C34: 0.12159143 | E34: =A34 -> 15 | F34: =B34/12.0107*1000 -> 66.272574 | G34: =C34/14.0067*1000 -> 8.6809476
A35: 16 | B35: 0.86818 | C35: 0.12881143 | E35: =A35 -> 16 | F35: =B35/12.0107*1000 -> 72.28388 | G35: =C35/14.0067*1000 -> 9.1964152
A36: 17 | B36: 1.09488 | C36: 0.13422143 | E36: =A36 -> 17 | F36: =B36/12.0107*1000 -> 91.158717 | G36: =C36/14.0067*1000 -> 9.5826589
A37: 18 | B37: 0.78638 | C37: 0.14486143 | E37: =A37 -> 18 | F37: =B37/12.0107*1000 -> 65.473286 | G37: =C37/14.0067*1000 -> 10.342295
A38: 19 | B38: 0.54688 | C38: 0.10818143 | E38: =A38 -> 19 | F38: =B38/12.0107*1000 -> 45.532733 | G38: =C38/14.0067*1000 -> 7.7235486
A39: 20 | B39: 0.81208 | C39: 0.13028143 | E39: =A39 -> 20 | F39: =B39/12.0107*1000 -> 67.613045 | G39: =C39/14.0067*1000 -> 9.301365
A40: DIW | B40: -0.00683 | C40: 0 | E40: =A40 -> DIW | F40: =B40/12.0107*1000 -> -0.56865961 | G40: =C40/14.0067*1000 -> 0
A41: LNSW | B41: 0.8769 | C41: 0.06 | E41: =A41 -> LNSW | F41: =B41/12.0107*1000 -> 73.0099 | G41: =C41/14.0067*1000 -> 4.2836642
A42: DSWR [B24,L05-24] | B42: 0.51078 | C42: 0.44507143 | E42: =A42 -> DSWR [B24,L05-24] | F42: =B42/12.0107*1000 -> 42.52708 | G42: =C42/14.0067*1000 -> 31.775609
A43: 21 | B43: 0.91468 | C43: 0.13541143 | E43: =A43 -> 21 | F43: =B43/12.0107*1000 -> 76.155428 | G43: =C43/14.0067*1000 -> 9.6676183
A44: 22 | B44: 0.84928 | C44: 0.13078143 | E44: =A44 -> 22 | F44: =B44/12.0107*1000 -> 70.710283 | G44: =C44/14.0067*1000 -> 9.3370622
...

Sheet Run File 12.13.24
A1: System | B1: TOCReg | D1: Deep Seawater Reference Material
A2: S/W Version | B2: 1
A3: User | B3: A.Whitworth | D3: NPOC certified reference value 0.504-0.516 mg/L: 42-43 uM
A4: Date | B4: 45639 | D4: TN certified reference value 0.434-0.448 mg/L: 31-32 uM
A5: Comments | B5: Nelson/Rochette-Yu Tsuen (11/08/24)
A9: Standards
A10: Range | B10: 0-5mg/L
A12: Raw data (mg/L) | E12: Unit conversion
A13: Sample | B13: NPOC (mg/L) | C13: TN (mg/L) | E13: Sample | F13: NPOC (uM) | G13: TN (uM)
A14: DIW | B14: -0.00049 | C14: 0 | E14: =A14 -> DIW | F14: =B14/12.0107*1000 -> -0.040796956 | G14: =C14/14.0067*1000 -> 0
A15: LNSW | B15: 0.8951 | C15: 0.06018 | E15: =A15 -> LNSW | F15: =B15/12.0107*1000 -> 74.525215 | G15: =C15/14.0067*1000 -> 4.2965152
A16: DSWR [B24,L05-24] | B16: 0.50678333 | C16: 0.44143333 | E16: =A16 -> DSWR [B24,L05-24] | F16: =B16/12.0107*1000 -> 42.194321 | G16: =C16/14.0067*1000 -> 31.51587
A17: 61 | B17: 0.81768333 | C17: 0.14613333 | E17: =A17 -> 61 | F17: =B17/12.0107*1000 -> 68.079573 | G17: =C17/14.0067*1000 -> 10.433102
A18: 62 | B18: 0.75878333 | C18: 0.12892333 | E18: =A18 -> 62 | F18: =B18/12.0107*1000 -> 63.175613 | G18: =C18/14.0067*1000 -> 9.2044046
A19: 63 | B19: 0.53538333 | C19: 0.12426333 | E19: =A19 -> 63 | F19: =B19/12.0107*1000 -> 44.575531 | G19: =C19/14.0067*1000 -> 8.8717066
A20: 64 | B20: 0.33498333 | C20: 0.10943333 | E20: =A20 -> 64 | F20: =B20/12.0107*1000 -> 27.890409 | G20: =C20/14.0067*1000 -> 7.8129276
A21: 65 | B21: 0.81898333 | C21: 0.14113333 | E21: =A21 -> 65 | F21: =B21/12.0107*1000 -> 68.18781 | G21: =C21/14.0067*1000 -> 10.07613
A22: 67 | B22: 0.76118333 | C22: 0.13028333 | E22: =A22 -> 67 | F22: =B22/12.0107*1000 -> 63.375435 | G22: =C22/14.0067*1000 -> 9.3015009
A23: 68 | B23: 0.78948333 | C23: 0.13574333 | E23: =A23 -> 68 | F23: =B23/12.0107*1000 -> 65.731667 | G23: =C23/14.0067*1000 -> 9.6913144
A24: DIW | B24: -0.00874 | C24: 0 | E24: =A24 -> DIW | F24: =B24/12.0107*1000 -> -0.72768448 | G24: =C24/14.0067*1000 -> 0
A25: LNSW | B25: 0.8737 | C25: 0.05459 | E25: =A25 -> LNSW | F25: =B25/12.0107*1000 -> 72.74347 | G25: =C25/14.0067*1000 -> 3.8974205
A26: DSWR [B24,L05-24] | B26: 0.51298333 | C26: 0.44323333 | E26: =A26 -> DSWR [B24,L05-24] | F26: =B26/12.0107*1000 -> 42.710528 | G26: =C26/14.0067*1000 -> 31.64438
A27: 70 | B27: 0.76678333 | C27: 0.13294333 | E27: =A27 -> 70 | F27: =B27/12.0107*1000 -> 63.841686 | G27: =C27/14.0067*1000 -> 9.4914101
A28: 71 | B28: 0.82728333 | C28: 0.14579333 | E28: =A28 -> 71 | F28: =B28/12.0107*1000 -> 68.878861 | G28: =C28/14.0067*1000 -> 10.408828
A29: 73 | B29: 0.77898333 | C29: 0.14734333 | E29: =A29 -> 73 | F29: =B29/12.0107*1000 -> 64.857447 | G29: =C29/14.0067*1000 -> 10.519489
A30: 74 | B30: 1.8048833 | C30: 2.9840333 | E30: =A30 -> 74 | F30: =B30/12.0107*1000 -> 150.27295 | G30: =C30/14.0067*1000 -> 213.04328
A31: DIW | B31: -0.001 | C31: 0 | E31: =A31 -> DIW | F31: =B31/12.0107*1000 -> -0.083259094 | G31: =C31/14.0067*1000 -> 0
A32: LNSW | B32: 0.8634 | C32: 0.0542 | E32: =A32 -> LNSW | F32: =B32/12.0107*1000 -> 71.885902 | G32: =C32/14.0067*1000 -> 3.8695767
A33: DSWR [B24,L05-24] | B33: 0.50998333 | C33: 0.43803333 | E33: =A33 -> DSWR [B24,L05-24] | F33: =B33/12.0107*1000 -> 42.46075 | G33: =C33/14.0067*1000 -> 31.273129
