Workbook

Sheet Final Results
C1: Data Provided by:
C2: SOEST Laboratory for
C3: Analtyical Biogeochemistry (S-LAB)
C4: University of Hawaii at Manoa
C5: 1000 Pope Rd
C6: Honolulu, HI 96822
C7: 808-956-5878
C9: Date Samples Received: | E9: 45560
C11: Project: | D11: Nelson/Rochette-Yu Tsuen
A13: Sample | B13: NPOC (mg/L) | C13: TN (mg/L) | E13: Sample | F13: NPOC (uM) | G13: TN (uM)
A14: ='Run File 09.10.24'!A17 -> F1 6/6/24 21:00 | B14: ='Run File 09.10.24'!B17 -> 5.4242667 | C14: ='Run File 09.10.24'!C17 -> 0.182525 | E14: =A14 -> F1 6/6/24 21:00 | F14: =B14/12.0107*1000 -> 451.61953 | G14: =C14/14.0067*1000 -> 13.031264
A15: ='Run File 09.10.24'!A18 -> T1 6/6/24 21:00 | B15: ='Run File 09.10.24'!B18 -> 1.2832667 | C15: ='Run File 09.10.24'!C18 -> 0.162695 | E15: =A15 -> T1 6/6/24 21:00 | F15: =B15/12.0107*1000 -> 106.84362 | G15: =C15/14.0067*1000 -> 11.615513
A16: ='Run File 09.10.24'!A19 -> T2 6/6/24 21:00 | B16: ='Run File 09.10.24'!B19 -> 1.3752667 | C16: ='Run File 09.10.24'!C19 -> 0.151215 | E16: =A16 -> T2 6/6/24 21:00 | F16: =B16/12.0107*1000 -> 114.50346 | G16: =C16/14.0067*1000 -> 10.795905
A17: ='Run File 09.10.24'!A20 -> T3 6/6/24 21:00 | B17: ='Run File 09.10.24'!B20 -> 1.4882667 | C17: ='Run File 09.10.24'!C20 -> 0.165725 | E17: =A17 -> T3 6/6/24 21:00 | F17: =B17/12.0107*1000 -> 123.91173 | G17: =C17/14.0067*1000 -> 11.831838
A18: ='Run File 09.10.24'!A21 -> T4 6/6/24 21:00 | B18: ='Run File 09.10.24'!B21 -> 1.2792667 | C18: ='Run File 09.10.24'!C21 -> 0.170525 | E18: =A18 -> T4 6/6/24 21:00 | F18: =B18/12.0107*1000 -> 106.51058 | G18: =C18/14.0067*1000 -> 12.174531
A19: ='Run File 09.10.24'!A22 -> T5 6/6/24 21:00 | B19: ='Run File 09.10.24'!B22 -> 1.2342667 | C19: ='Run File 09.10.24'!C22 -> 0.155635 | E19: =A19 -> T5 6/6/24 21:00 | F19: =B19/12.0107*1000 -> 102.76392 | G19: =C19/14.0067*1000 -> 11.111468
A20: ='Run File 09.10.24'!A23 -> T6 6/6/24 21:00 | B20: ='Run File 09.10.24'!B23 -> 1.0782667 | C20: ='Run File 09.10.24'!C23 -> 0.168025 | E20: =A20 -> T6 6/6/24 21:00 | F20: =B20/12.0107*1000 -> 89.775506 | G20: =C20/14.0067*1000 -> 11.996045
A21: ='Run File 09.10.24'!A27 -> T7 6/6/24 21:00 | B21: ='Run File 09.10.24'!B27 -> 1.2592667 | C21: ='Run File 09.10.24'!C27 -> 0.181825 | E21: =A21 -> T7 6/6/24 21:00 | F21: =B21/12.0107*1000 -> 104.8454 | G21: =C21/14.0067*1000 -> 12.981288
A22: ='Run File 09.10.24'!A28 -> T8 6/6/24 21:00 | B22: ='Run File 09.10.24'!B28 -> 1.1412667 | C22: ='Run File 09.10.24'!C28 -> 0.152175 | E22: =A22 -> T8 6/6/24 21:00 | F22: =B22/12.0107*1000 -> 95.020829 | G22: =C22/14.0067*1000 -> 10.864443
A23: ='Run File 09.10.24'!A29 -> T9 6/6/24 21:00 | B23: ='Run File 09.10.24'!B29 -> 1.6742667 | C23: ='Run File 09.10.24'!C29 -> 0.170725 | E23: =A23 -> T9 6/6/24 21:00 | F23: =B23/12.0107*1000 -> 139.39793 | G23: =C23/14.0067*1000 -> 12.18881
A24: ='Run File 09.10.24'!A30 -> T10 6/6/24 21:00 | B24: ='Run File 09.10.24'!B30 -> 1.1522667 | C24: ='Run File 09.10.24'!C30 -> 0.186425 | E24: =A24 -> T10 6/6/24 21:00 | F24: =B24/12.0107*1000 -> 95.936679 | G24: =C24/14.0067*1000 -> 13.309702
A25: ='Run File 09.10.24'!A31 -> T11 6/6/24 21:00 | B25: ='Run File 09.10.24'!B31 -> 1.2762667 | C25: ='Run File 09.10.24'!C31 -> 0.190825 | E25: =A25 -> T11 6/6/24 21:00 | F25: =B25/12.0107*1000 -> 106.26081 | G25: =C25/14.0067*1000 -> 13.623837
A26: ='Run File 09.10.24'!A32 -> T12 6/6/24 21:00 | B26: ='Run File 09.10.24'!B32 -> 1.1772667 | C26: ='Run File 09.10.24'!C32 -> 0.170625 | E26: =A26 -> T12 6/6/24 21:00 | F26: =B26/12.0107*1000 -> 98.018156 | G26: =C26/14.0067*1000 -> 12.18167
A27: ='Run File 09.10.24'!A33 -> T13 6/6/24 21:00 | B27: ='Run File 09.10.24'!B33 -> 1.1242667 | C27: ='Run File 09.10.24'!C33 -> 0.163315 | E27: =A27 -> T13 6/6/24 21:00 | F27: =B27/12.0107*1000 -> 93.605424 | G27: =C27/14.0067*1000 -> 11.659777
A28: ='Run File 09.10.24'!A34 -> T14 6/6/24 21:00 | B28: ='Run File 09.10.24'!B34 -> 1.1392667 | C28: ='Run File 09.10.24'!C34 -> 0.149915 | E28: =A28 -> T14 6/6/24 21:00 | F28: =B28/12.0107*1000 -> 94.85431 | G28: =C28/14.0067*1000 -> 10.703092
A29: ='Run File 09.10.24'!A35 -> T15 6/6/24 21:00 | B29: ='Run File 09.10.24'!B35 -> 1.2302667 | C29: ='Run File 09.10.24'!C35 -> 0.280125 | E29: =A29 -> T15 6/6/24 21:00 | F29: =B29/12.0107*1000 -> 102.43089 | G29: =C29/14.0067*1000 -> 19.999357
A30: ='Run File 09.10.24'!A36 -> T16 6/6/24 21:00 | B30: ='Run File 09.10.24'!B36 -> 1.1142667 | C30: ='Run File 09.10.24'!C36 -> 0.160315 | E30: =A30 -> T16 6/6/24 21:00 | F30: =B30/12.0107*1000 -> 92.772833 | G30: =C30/14.0067*1000 -> 11.445594
A31: ='Run File 09.10.24'!A40 -> F1 6/11/24 12:00 | B31: ='Run File 09.10.24'!B40 -> 4.3752667 | C31: ='Run File 09.10.24'!C40 -> 0.168925 | E31: =A31 -> F1 6/11/24 12:00 | F31: =B31/12.0107*1000 -> 364.28074 | G31: =C31/14.0067*1000 -> 12.0603
A32: ='Run File 09.10.24'!A41 -> F2 6/11/24 12:00 | B32: ='Run File 09.10.24'!B41 -> 1.0002667 | C32: ='Run File 09.10.24'!C41 -> 0.152775 | E32: =A32 -> F2 6/11/24 12:00 | F32: =B32/12.0107*1000 -> 83.281296 | G32: =C32/14.0067*1000 -> 10.90728
A33: ='Run File 09.10.24'!A42 -> T1 6/11/24 12:00 | B33: ='Run File 09.10.24'!B42 -> 3.5862667 | C33: ='Run File 09.10.24'!C42 -> 0.202125 | E33: =A33 -> T1 6/11/24 12:00 | F33: =B33/12.0107*1000 -> 298.58931 | G33: =C33/14.0067*1000 -> 14.430594
A34: ='Run File 09.10.24'!A43 -> T2 6/11/24 12:00 | B34: ='Run File 09.10.24'!B43 -> 3.9932667 | C34: ='Run File 09.10.24'!C43 -> 0.162145 | E34: =A34 -> T2 6/11/24 12:00 | F34: =B34/12.0107*1000 -> 332.47576 | G34: =C34/14.0067*1000 -> 11.576246
A35: ='Run File 09.10.24'!A44 -> T3 6/11/24 12:00 | B35: ='Run File 09.10.24'!B44 -> 1.0092667 | C35: ='Run File 09.10.24'!C44 -> 0.176125 | E35: =A35 -> T3 6/11/24 12:00 | F35: =B35/12.0107*1000 -> 84.030628 | G35: =C35/14.0067*1000 -> 12.574339
A36: ='Run File 09.10.24'!A45 -> T4 6/11/24 12:00 | B36: ='Run File 09.10.24'!B45 -> 3.5312667 | C36: ='Run File 09.10.24'!C45 -> 0.163075 | E36: =A36 -> T4 6/11/24 12:00 | F36: =B36/12.0107*1000 -> 294.01006 | G36: =C36/14.0067*1000 -> 11.642642
A37: ='Run File 09.10.24'!A46 -> T5 6/11/24 12:00 | B37: ='Run File 09.10.24'!B46 -> 1.7662667 | C37: ='Run File 09.10.24'!C46 -> 0.311625 | E37: =A37 -> T5 6/11/24 12:00 | F37: =B37/12.0107*1000 -> 147.05776 | G37: =C37/14.0067*1000 -> 22.248281
A38: ='Run File 09.10.24'!A47 -> T6 6/11/24 12:00 | B38: ='Run File 09.10.24'!B47 -> 1.5542667 | C38: ='Run File 09.10.24'!C47 -> 0.327825 | E38: =A38 -> T6 6/11/24 12:00 | F38: =B38/12.0107*1000 -> 129.40683 | G38: =C38/14.0067*1000 -> 23.404871
A39: ='Run File 09.10.24'!A48 -> T7 6/11/24 12:00 | B39: ='Run File 09.10.24'!B48 -> 1.4202667 | C39: ='Run File 09.10.24'!C48 -> 0.328425 | E39: =A39 -> T7 6/11/24 12:00 | F39: =B39/12.0107*1000 -> 118.25012 | G39: =C39/14.0067*1000 -> 23.447707
A40: ='Run File 09.10.24'!A49 -> T8 6/11/24 12:00 | B40: ='Run File 09.10.24'!B49 -> 1.6752667 | C40: ='Run File 09.10.24'!C49 -> 0.394025 | E40: =A40 -> T8 6/11/24 12:00 | F40: =B40/12.0107*1000 -> 139.48118 | G40: =C40/14.0067*1000 -> 28.13118
A41: ='Run File 09.10.24'!A53 -> T9 6/11/24 12:00 | B41: ='Run File 09.10.24'!B53 -> 2.3132667 | C41: ='Run File 09.10.24'!C53 -> 0.430825 | E41: =A41 -> T9 6/11/24 12:00 | F41: =B41/12.0107*1000 -> 192.60049 | G41: =C41/14.0067*1000 -> 30.758494
A42: ='Run File 09.10.24'!A54 -> T10 6/11/24 12:00 | B42: ='Run File 09.10.24'!B54 -> 1.5602667 | C42: ='Run File 09.10.24'!C54 -> 0.303125 | E42: =A42 -> T10 6/11/24 12:00 | F42: =B42/12.0107*1000 -> 129.90639 | G42: =C42/14.0067*1000 -> 21.641429
A43: ='Run File 09.10.24'!A55 -> T11 6/11/24 12:00 | B43: ='Run File 09.10.24'!B55 -> 2.3832667 | C43: ='Run File 09.10.24'!C55 -> 0.317825 | E43: =A43 -> T11 6/11/24 12:00 | F43: =B43/12.0107*1000 -> 198.42862 | G43: =C43/14.0067*1000 -> 22.690926
...

Sheet Run File 09.10.24
A1: System | B1: TOCReg | D1: Deep Seawater Reference Material
A2: S/W Version | B2: 1
A3: User | B3: A.Whitworth | D3: NPOC certified reference value 0.504-0.516 mg/L: 42-43 uM
A4: Date | B4: 45545 | D4: TN certified reference value 0.434-0.448 mg/L: 31-32 uM
A5: Comments | B5: Nelson/Rochette-Yu Tsuen (9/25/24)
A9: Standards
A10: Range | B10: 0-5mg/L
A12: Raw data (mg/L) | E12: Unit conversion
A13: Sample | B13: NPOC (mg/L) | C13: TN (mg/L) | E13: Sample | F13: NPOC (uM) | G13: TN (uM)
A14: DIW | B14: -0.00929 | C14: 0 | E14: =A14 -> DIW | F14: =B14/12.0107*1000 -> -0.77347698 | G14: =C14/14.0067*1000 -> 0
A15: LNSW | B15: 0.9565 | C15: 0.06452 | E15: =A15 -> LNSW | F15: =B15/12.0107*1000 -> 79.637323 | G15: =C15/14.0067*1000 -> 4.606367
A16: DSWR [B24,L05-24] | B16: 0.51306667 | C16: 0.439825 | E16: =A16 -> DSWR [B24,L05-24] | F16: =B16/12.0107*1000 -> 42.717466 | G16: =C16/14.0067*1000 -> 31.401044
A17: F1 6/6/24 21:00 | B17: 5.4242667 | C17: 0.182525 | E17: =A17 -> F1 6/6/24 21:00 | F17: =B17/12.0107*1000 -> 451.61953 | G17: =C17/14.0067*1000 -> 13.031264
A18: T1 6/6/24 21:00 | B18: 1.2832667 | C18: 0.162695 | E18: =A18 -> T1 6/6/24 21:00 | F18: =B18/12.0107*1000 -> 106.84362 | G18: =C18/14.0067*1000 -> 11.615513
A19: T2 6/6/24 21:00 | B19: 1.3752667 | C19: 0.151215 | E19: =A19 -> T2 6/6/24 21:00 | F19: =B19/12.0107*1000 -> 114.50346 | G19: =C19/14.0067*1000 -> 10.795905
A20: T3 6/6/24 21:00 | B20: 1.4882667 | C20: 0.165725 | E20: =A20 -> T3 6/6/24 21:00 | F20: =B20/12.0107*1000 -> 123.91173 | G20: =C20/14.0067*1000 -> 11.831838
A21: T4 6/6/24 21:00 | B21: 1.2792667 | C21: 0.170525 | E21: =A21 -> T4 6/6/24 21:00 | F21: =B21/12.0107*1000 -> 106.51058 | G21: =C21/14.0067*1000 -> 12.174531
A22: T5 6/6/24 21:00 | B22: 1.2342667 | C22: 0.155635 | E22: =A22 -> T5 6/6/24 21:00 | F22: =B22/12.0107*1000 -> 102.76392 | G22: =C22/14.0067*1000 -> 11.111468
A23: T6 6/6/24 21:00 | B23: 1.0782667 | C23: 0.168025 | E23: =A23 -> T6 6/6/24 21:00 | F23: =B23/12.0107*1000 -> 89.775506 | G23: =C23/14.0067*1000 -> 11.996045
A24: DIW | B24: -0.0078 | C24: 0 | E24: =A24 -> DIW | F24: =B24/12.0107*1000 -> -0.64942093 | G24: =C24/14.0067*1000 -> 0
A25: LNSW | B25: 0.8939 | C25: 0.05885 | E25: =A25 -> LNSW | F25: =B25/12.0107*1000 -> 74.425304 | G25: =C25/14.0067*1000 -> 4.2015607
... A78: DSWR [B24,L05-24] | B78: 0.50426667 | C78: 0.442725 | E78: =A78 -> DSWR [B24,L05-24] | F78: =B78/12.0107*1000 -> 41.984786 | G78: =C78/14.0067*1000 -> 31.608088

Sheet Run File 10.15.24
A1: System | B1: TOCReg | D1: Deep Seawater Reference Material
A2: S/W Version | B2: 1
A3: User | B3: A.Whitworth | D3: NPOC certified reference value 0.504-0.516 mg/L: 42-43 uM
A4: Date | B4: 45580 | D4: TN certified reference value 0.434-0.448 mg/L: 31-32 uM
A5: Comments | B5: Nelson/Rochette-Yu Tsuen (9/25/24)
A9: Standards
A10: Range | B10: 0-5mg/L
A12: Raw data (mg/L) | E12: Unit conversion
A13: Sample | B13: NPOC (mg/L) | C13: TN (mg/L) | E13: Sample | F13: NPOC (uM) | G13: TN (uM)
A14: DIW | B14: 0.00381 | C14: 0 | E14: =A14 -> DIW | F14: =B14/12.0107*1000 -> 0.31721715 | G14: =C14/14.0067*1000 -> 0
A15: LNSW | B15: 0.9514 | C15: 0.05719 | E15: =A15 -> LNSW | F15: =B15/12.0107*1000 -> 79.212702 | G15: =C15/14.0067*1000 -> 4.083046
A16: DSWR [B24,L05-24] | B16: 0.50490833 | C16: 0.444475 | E16: =A16 -> DSWR [B24,L05-24] | F16: =B16/12.0107*1000 -> 42.03821 | G16: =C16/14.0067*1000 -> 31.733028
A17: T11 6/11/24 21:00 | B17: 2.4466083 | C17: 0.461575 | E17: =A17 -> T11 6/11/24 21:00 | F17: =B17/12.0107*1000 -> 203.70239 | G17: =C17/14.0067*1000 -> 32.953872
A18: T12 6/11/24 21:00 | B18: 1.1326083 | C18: 0.410075 | E18: =A18 -> T12 6/11/24 21:00 | F18: =B18/12.0107*1000 -> 94.299944 | G18: =C18/14.0067*1000 -> 29.27706
A19: T13 6/11/24 21:00 | B19: 1.6806083 | C19: 0.490175 | E19: =A19 -> T13 6/11/24 21:00 | F19: =B19/12.0107*1000 -> 139.92593 | G19: =C19/14.0067*1000 -> 34.995752
A20: T14 6/11/24 21:00 | B20: 1.0966083 | C20: 0.463675 | E20: =A20 -> T14 6/11/24 21:00 | F20: =B20/12.0107*1000 -> 91.302616 | G20: =C20/14.0067*1000 -> 33.1038
A21: T15 6/11/24 21:00 | B21: 2.8256083 | C21: 0.449375 | E21: =A21 -> T15 6/11/24 21:00 | F21: =B21/12.0107*1000 -> 235.25759 | G21: =C21/14.0067*1000 -> 32.08286
A22: T16 6/11/24 21:00 | B22: 1.3186083 | C22: 0.374775 | E22: =A22 -> T16 6/11/24 21:00 | F22: =B22/12.0107*1000 -> 109.78614 | G22: =C22/14.0067*1000 -> 26.756838
A23: IN_1 6/16/24 12:00 | B23: 1.2816083 | C23: 0.420775 | E23: =A23 -> IN_1 6/16/24 12:00 | F23: =B23/12.0107*1000 -> 106.70555 | G23: =C23/14.0067*1000 -> 30.04098
A24: IN_2 6/16/24 12:00 | B24: 1.0766083 | C24: 0.379875 | E24: =A24 -> IN_2 6/16/24 12:00 | F24: =B24/12.0107*1000 -> 89.637434 | G24: =C24/14.0067*1000 -> 27.120949
A25: T7 6/16/24 12:00 | B25: 1.0706083 | C25: 0.345775 | E25: =A25 -> T7 6/16/24 12:00 | F25: =B25/12.0107*1000 -> 89.13788 | G25: =C25/14.0067*1000 -> 24.6864
... A81: DSWR [B24,L05-24] | B81: 0.50700833 | C81: 0.439375 | E81: =A81 -> DSWR [B24,L05-24] | F81: =B81/12.0107*1000 -> 42.213054 | G81: =C81/14.0067*1000 -> 31.368916

Sheet Run File 10.22.24
A1: System | B1: TOCReg | D1: Deep Seawater Reference Material
A2: S/W Version | B2: 1
A3: User | B3: A.Whitworth | D3: NPOC certified reference value 0.500-0.521mg/L: 41.6-43.4 uM
A4: Date | B4: 45587 | D4: TN certified reference value 0.423-0.450 mg/L: 30.2-32 uM
A5: Comments | B5: Nelson/Rochette-Yu Tsuen (9/25/24)
A9: Standards
A10: Range | B10: 0-5mg/L
A12: Raw data (mg/L) | E12: Unit conversion
A13: Sample | B13: NPOC (mg/L) | C13: TN (mg/L) | E13: Sample | F13: NPOC (uM) | G13: TN (uM)
A14: DIW | B14: -0.03683 | C14: 0 | E14: =A14 -> DIW | F14: =B14/12.0107*1000 -> -3.0664324 | G14: =C14/14.0067*1000 -> 0
A15: LNSW | B15: 0.9404 | C15: 0.05862 | E15: =A15 -> LNSW | F15: =B15/12.0107*1000 -> 78.296852 | G15: =C15/14.0067*1000 -> 4.18514
A16: DSWR [B24,L05-24] | B16: 0.52078333 | C16: 0.44058333 | E16: =A16 -> DSWR [B24,L05-24] | F16: =B16/12.0107*1000 -> 43.359948 | G16: =C16/14.0067*1000 -> 31.455185
A17: T7 6/20/24 9PM | B17: 1.0236833 | C17: 0.44308333 | E17: =A17 -> T7 6/20/24 9PM | F17: =B17/12.0107*1000 -> 85.230947 | G17: =C17/14.0067*1000 -> 31.633671
A18: T8 6/20/24 9PM | B18: 1.0091833 | C18: 0.29708333 | E18: =A18 -> T8 6/20/24 9PM | F18: =B18/12.0107*1000 -> 84.02369 | G18: =C18/14.0067*1000 -> 21.210088
A19: T9 6/20/24 9PM | B19: 0.91398333 | C19: 0.35208333 | E19: =A19 -> T9 6/20/24 9PM | F19: =B19/12.0107*1000 -> 76.097424 | G19: =C19/14.0067*1000 -> 25.13678
A20: T10 6/20/24 9PM | B20: 1.0156833 | C20: 0.38878333 | E20: =A20 -> T10 6/20/24 9PM | F20: =B20/12.0107*1000 -> 84.564874 | G20: =C20/14.0067*1000 -> 27.756954
A21: T11 6/20/24 9PM | B21: 1.7996833 | C21: 0.43118333 | E21: =A21 -> T11 6/20/24 9PM | F21: =B21/12.0107*1000 -> 149.84 | G21: =C21/14.0067*1000 -> 30.784077
A22: T12 6/20/24 9PM | B22: 2.4796833 | C22: 0.52578333 | E22: =A22 -> T12 6/20/24 9PM | F22: =B22/12.0107*1000 -> 206.45619 | G22: =C22/14.0067*1000 -> 37.537988
A23: T13 6/20/24 9PM | B23: 1.0406833 | C23: 0.39438333 | E23: =A23 -> T13 6/20/24 9PM | F23: =B23/12.0107*1000 -> 86.646351 | G23: =C23/14.0067*1000 -> 28.156763
A24: T14 6/20/24 9PM | B24: 1.6526833 | C24: 0.63658333 | E24: =A24 -> T14 6/20/24 9PM | F24: =B24/12.0107*1000 -> 137.60092 | G24: =C24/14.0067*1000 -> 45.448488
A25: T15 6/20/24 9PM | B25: 1.1156833 | C25: 0.25168333 | E25: =A25 -> T15 6/20/24 9PM | F25: =B25/12.0107*1000 -> 92.890783 | G25: =C25/14.0067*1000 -> 17.968782
... A42: DSWR [B24,L05-24] | B42: 0.51838333 | C42: 0.43588333 | E42: =A42 -> DSWR [B24,L05-24] | F42: =B42/12.0107*1000 -> 43.160127 | G42: =C42/14.0067*1000 -> 31.119631

Sheet Run File 11.14.24
A1: System | B1: TOCReg | D1: Deep Seawater Reference Material
A2: S/W Version | B2: 1
A3: User | B3: A.Whitworth | D3: NPOC certified reference value 0.504-0.516 mg/L: 42-43 uM
A4: Date | B4: 45610 | D4: TN certified reference value 0.434-0.448 mg/L: 31-32 uM
A5: Comments | B5: Nelson/Rochette-Yu Tsuen (9/25/24)
A9: Standards
A10: Range | B10: 0-5mg/L
A12: Raw data (mg/L) | E12: Unit conversion
A13: Sample | B13: NPOC (mg/L) | C13: TN (mg/L) | E13: Sample | F13: NPOC (uM) | G13: TN (uM)
A14: DIW | B14: -0.00362 | C14: 0 | E14: =A14 -> DIW | F14: =B14/12.0107*1000 -> -0.30139792 | G14: =C14/14.0067*1000 -> 0
A15: LNSW | B15: 0.8641 | C15: 0.05042 | E15: =A15 -> LNSW | F15: =B15/12.0107*1000 -> 71.944183 | G15: =C15/14.0067*1000 -> 3.5997059
A16: DSWR [B24,L05-24] | B16: 0.51223333 | C16: 0.43455833 | E16: =A16 -> DSWR [B24,L05-24] | F16: =B16/12.0107*1000 -> 42.648083 | G16: =C16/14.0067*1000 -> 31.025033
A17: T9 6/20/24 NOON | B17: 1.0996333 | C17: 0.24745833 | E17: =A17 -> T9 6/20/24 NOON | F17: =B17/12.0107*1000 -> 91.554475 | G17: =C17/14.0067*1000 -> 17.66714
A18: T10 6/20/24 NOON | B18: 1.2486333 | C18: 0.24415833 | E18: =A18 -> T10 6/20/24 NOON | F18: =B18/12.0107*1000 -> 103.96008 | G18: =C18/14.0067*1000 -> 17.431539
A19: T11 6/20/24 NOON | B19: 1.3466333 | C19: 0.25505833 | E19: =A19 -> T11 6/20/24 NOON | F19: =B19/12.0107*1000 -> 112.11947 | G19: =C19/14.0067*1000 -> 18.209738
A20: T12 6/20/24 NOON | B20: 1.2176333 | C20: 0.38375833 | E20: =A20 -> T12 6/20/24 NOON | F20: =B20/12.0107*1000 -> 101.37905 | G20: =C20/14.0067*1000 -> 27.398198
A21: T13 6/20/24 NOON | B21: 0.93483333 | C21: 0.33915833 | E21: =A21 -> T13 6/20/24 NOON | F21: =B21/12.0107*1000 -> 77.833376 | G21: =C21/14.0067*1000 -> 24.214007
A22: T14 6/20/24 NOON | B22: 1.3726333 | C22: 0.25745833 | E22: =A22 -> T14 6/20/24 NOON | F22: =B22/12.0107*1000 -> 114.28421 | G22: =C22/14.0067*1000 -> 18.381084
A23: T15 6/20/24 NOON | B23: 4.5136333 | C23: 0.65795833 | E23: =A23 -> T15 6/20/24 NOON | F23: =B23/12.0107*1000 -> 375.80102 | G23: =C23/14.0067*1000 -> 46.974543
A24: T16 6/20/24 NOON | B24: 1.0676333 | C24: 0.50005833 | E24: =A24 -> T16 6/20/24 NOON | F24: =B24/12.0107*1000 -> 88.890184 | G24: =C24/14.0067*1000 -> 35.701367
A25: C1 6/26/24 14:00 | B25: 1.9116333 | C25: 0.39335833 | E25: =A25 -> C1 6/26/24 14:00 | F25: =B25/12.0107*1000 -> 159.16086 | G25: =C25/14.0067*1000 -> 28.083584
... A49: DSWR [B24,L05-24] | B49: 0.51323333 | C49: 0.43385833 | E49: =A49 -> DSWR [B24,L05-24] | F49: =B49/12.0107*1000 -> 42.731342 | G49: =C49/14.0067*1000 -> 30.975057
